Workbook
Name Xперемен: [1]Интервалы!$B$53:$B$113
Name Yперемен: [1]Интервалы!$C$53:$C$113

Sheet Вводные
B2: Цели 2025–2029, тыс. руб.
C3: А | K3: Б | S3: В | AA3: Г
D4: 2025 факт | E4: 2026 | F4: 2027 | G4: 2028 | H4: 2029 | I4: 2030 | L4: 2025 факт | M4: 2026 | N4: 2027 | O4: 2028 | P4: 2029 | Q4: 2030 | T4: 2025 факт | U4: 2026 | V4: 2027 | W4: 2028 | X4: 2029 | Y4: 2030 | AB4: 2025 факт | AC4: 2026 | AD4: 2027 | AE4: 2028 | AF4: 2029 | AG4: 2030
B5: Выручка | C5: 2030 х2 к 2025 | D5: 51502 | E5: 59031.592 | F5: 67732.849 | G5: 77797.95 | H5: 89452.083 | I5: =D5*2 -> 103004 | K5: 2030 х2 к 2025 | L5: 43215.028 | M5: 49498.493 | N5: 56824.27 | O5: 65274.039 | P5: 75065.145 | Q5: =L5*2 -> 86430.056 | S5: 2030 х3.5 к 2025 | T5: 24565 | U5: 30829.075 | V5: 38998.78 | W5: 49918.438 | X5: 64644.378 | Y5: =T5*3.5 -> 85977.5 | AA5: 2030 х2 к 2025 | AB5: 7911.8422 | AC5: 8995.7646 | AD5: 10282.159 | AE5: 11803.918 | AF5: 13633.526 | AG5: =AB5*2 -> 15823.684 | AI5: =D5+L5+T5+AB5 -> 127193.87
B6: Прирост год к году, % | D6: 0.145 | E6: =E5/D5-1 -> 0.1462 | F6: =F5/E5-1 -> 0.1474 | G6: =G5/F5-1 -> 0.1486 | H6: =H5/G5-1 -> 0.1498 | I6: =I5/H5-1 -> 0.15149917 | L6: 0.144 | M6: 0.1454 | N6: 0.148 | O6: 0.1487 | P6: 0.15 | Q6: =Q5/P5-1 -> 0.15140064 | T6: 0.25 | U6: 0.255 | V6: 0.265 | W6: 0.28 | X6: 0.295 | Y6: =Y5/X5-1 -> 0.33000739 | AB6: 0.133 | AC6: 0.137 | AD6: 0.143 | AE6: 0.148 | AF6: 0.155 | AG6: =AG5/AF5-1 -> 0.16064506
B7: Чистая прибыль | D7: =D68 -> 14154.75 | E7: 18299.794 | F7: 22487.306 | G7: 27540.474 | H7: 33633.983 | I7: =I8*I5 -> 41201.6 | L7: =L68 -> 7103.256 | M7: 9652.2061 | N7: 12842.285 | O7: 17232.346 | P7: 21018.24 | Q7: =Q8*Q5 -> 25929.017 | T7: =T68 -> 627 | U7: 2343.0097 | V7: 5966.8133 | W7: 13877.326 | X7: 21009.423 | Y7: =Y8*Y5 -> 34391 | AB7: =AB68 -> 1161.98 | AC7: 1664.2165 | AD7: 2364.8966 | AE7: 3246.0776 | AF7: 4158.2254 | AG7: =AG8*AG5 -> 5538.2896
B8: Чистая прибыль, % | C8: 2030 не < 40% | D8: =D7/D5 -> 0.27483884 | E8: 0.31 | F8: 0.332 | G8: 0.354 | H8: 0.376 | I8: 0.4 | K8: 2030 не < 30% | L8: =L7/L5 -> 0.16437004 | M8: 0.195 | N8: 0.226 | O8: 0.264 | P8: 0.28 | Q8: 0.3 | S8: 2030 не < 40% | T8: =T7/T5 -> 0.02552412 | U8: 0.076 | V8: 0.153 | W8: 0.278 | X8: 0.325 | Y8: 0.4 | AA8: 2030 не < 35% | AB8: =AB7/AB5 -> 0.14686592 | AC8: 0.185 | AD8: 0.23 | AE8: 0.275 | AF8: 0.305 | AG8: 0.35
B10: Информация по компании А от смежных подразделений
D11: 2025 факт | E11: 2026 | F11: 2027 | G11: 2028 | H11: 2029 | I11: 2030
B12: Инфляция, % | D12: 0.055 | E12: 0.05 | F12: 0.05 | G12: 0.05 | H12: 0.05 | I12: 0.05
B13: Индексация ЗП, % | D13: 0.065 | E13: 0.06 | F13: 0.06 | G13: 0.06 | H13: 0.06 | I13: 0.06
B14: Доп. персонал в отдел разработки, штат. ед. | D14: - | E14: 1 | F14: 1 | G14: 1 | H14: 1 | I14: 1
B15: Средняя заработная плата потенциального персонала, руб. | D15: - | E15: 100000 | F15: 100000 | G15: 100000 | H15: 100000 | I15: 100000
B16: Соц. налоги на человека, % | D16: - | E16: 0.3 | F16: 0.3 | G16: 0.3 | H16: 0.3 | I16: 0.3
B17: Количество платежей и переводов, всего | D17: 27210.141 | E17: 31342.454 | F17: 36102.411 | G17: 41585.355 | H17: 47901.115 | I17: 55176.204
B18: Стоимость привлечения платежа/перевода, руб. | D18: - | E18: 136.5 | F18: 126 | G18: 115.5 | H18: 105 | I18: 94.5
B19: Количество активных (платящих) пользователей, чел. | D19: 75718.78
B21: Реестр внутригрупповых операций*, тыс. руб.
C22: 2025 план | D22: 2025 факт | E22: 2026 | F22: 2027 | G22: 2028 | H22: 2029 | I22: 2030
B23: Компания А оказывает услуги платёжного сервиса компании Б | C23: 110 | D23: 110 | E23: 115.5 | F23: 121 | G23: 126.5 | H23: 132 | I23: 137.5
B24: Компания А приобретает аутсорсинговые услуги для осуществления текущей деятельности сервиса платежей и переводов у компании Б | C24: 1100 | D24: 1100 | E24: 1210 | F24: 1320 | G24: 1430 | H24: 1540 | I24: 1650
B25: Компания Б оказывает аутсорсинговые услуги компании В | C25: 77 | D25: 77 | E25: 88 | F25: 99 | G25: 110 | H25: 121 | I25: 132
B26: Компания В приобретает услуги платёжного сервиса у компании А | C26: 22 | D26: 22 | E26: 23.1 | F26: 24.255 | G26: 25.46775 | H26: 26.741138 | I26: 28.078194
B27: Компания В приобретает программное обеспечение для осуществления текущей деятельности трейдинговой платформы у компании Б | C27: 1210 | D27: 1210 | E27: 1320 | F27: 1320 | G27: 1320 | H27: 1320 | I27: 1320
B28: Компания Г приобретает услуги платёжного сервиса у компании А | C28: 2.2 | D28: 2.2 | E28: 3.3 | F28: 3.3 | G28: 3.3 | H28: 3.3 | I28: 3.3
B29: Компания Г приобретает аутсорсинговые услуги у компании Б | C29: 1.1 | D29: 1.1 | E29: 2.2 | F29: 2.2 | G29: 2.2 | H29: 2.2 | I29: 2.2
B30: Компания Г получила штраф за нарушение договорных обязательств от компании Б | C30: 0 | D30: 10 | E30: 0 | F30: 0 | G30: 0 | H30: 0 | I30: 0
B31: Компания А в прошлом периоде предоставила беспроцентный заём компании В
B32: платёж в части основного долга | C32: 600 | D32: 600 | E32: 600 | F32: 0 | G32: 0 | H32: 0 | I32: 0
B33: остаток долга на 31.12.2025 | C33: 600 | D33: 600 | E33: 0 | F33: 0 | G33: 0 | H33: 0 | I33: 0
B35: *При взаиморасчётах между участниками группы по их основным видам деятельности, исполнение обязательств всеми сторонами-участниками происходит одновременно
B37: Отчётность участников Группы Stand alone
B39: Отчёт о прибылях и убытках, тыс. руб.
C40: А | K40: Б | S40: В | AA40: Г
C41: 2025 план | D41: 2025 факт | E41: 2026 | F41: 2027 | G41: 2028 | H41: 2029 | I41: 2030 | K41: 2025 план | L41: 2025 факт | M41: 2026 | N41: 2027 | O41: 2028 | P41: 2029 | Q41: 2030 | S41: 2025 план | T41: 2025 факт | U41: 2026 | V41: 2027 | W41: 2028 | X41: 2029 | Y41: 2030 | AA41: 2025 план | AB41: 2025 факт | AC41: 2026 | AD41: 2027 | AE41: 2028 | AF41: 2029 | AG41: 2030
B42: Выручка от реализации | C42: =SUM(C43:C47) -> 51450 | D42: =SUM(D43:D47) -> 51502 | E42: =($D$42/$D$17)*E17 -> 59323.437 | F42: =($D$42/$D$17)*F17 -> 68332.847 | G42: =($D$42/$D$17)*G17 -> 78710.69 | H42: =($D$42/$D$17)*H17 -> 90664.845 | I42: =($D$42/$D$17)*I17 -> 104434.77 | K42: =SUM(K43:K47) -> 42500 | L42: =SUM(L43:L47) -> 43215.028 | M42: =SUM(M43:M47) -> 51144.985 | N42: =SUM(N43:N47) -> 60531.073 | O42: =SUM(O43:O47) -> 71640.855 | P42: =SUM(P43:P47) -> 84791.094 | Q42: =SUM(Q43:Q47) -> 100356.8 | S42: =SUM(S43:S47) -> 23700 | T42: =SUM(T43:T47) -> 24565 | U42: =SUM(U43:U47) -> 29797.345 | V42: =SUM(V43:V47) -> 37246.681 | W42: =SUM(W43:W47) -> 47675.752 | X42: =SUM(X43:X47) -> 63408.75 | Y42: =SUM(Y43:Y47) -> 85601.813 | AA42: =SUM(AA43:AA47) -> 8500 | AB42: =SUM(AB43:AB47) -> 7911.8422 | AC42: =SUM(AC43:AC47) -> 8873.1311 | AD42: =SUM(AD43:AD47) -> 9951.2165 | AE42: =SUM(AE43:AE47) -> 11160.289 | AF42: =SUM(AF43:AF47) -> 12516.264 | AG42: =SUM(AG43:AG47) -> 14036.991
B43: Комиссии за обработку платежей и переводов | C43: 51450 | D43: 51502 | E43: =E42 -> 59323.437 | F43: =F42 -> 68332.847 | G43: =G42 -> 78710.69 | H43: =H42 -> 90664.845 | I43: =I42 -> 104434.77 | K43: 0 | L43: 0 | M43: 0 | N43: 0 | O43: 0 | P43: 0 | Q43: 0 | S43: 0 | T43: 0 | U43: 0 | V43: 0 | W43: 0 | X43: 0 | Y43: 0 | AA43: 0 | AB43: 0 | AC43: 0 | AD43: 0 | AE43: 0 | AF43: 0 | AG43: 0
B44: Разработка программного обеспечения | C44: 0 | D44: 0 | K44: 27500 | L44: 28089.768 | M44: 33145.926 | N44: 39112.193 | O44: 46152.388 | P44: 54459.818 | Q44: 64262.585 | S44: 0 | T44: 0 | U44: 0 | V44: 0 | W44: 0 | X44: 0 | Y44: 0 | AA44: 0 | AB44: 0 | AC44: 0 | AD44: 0 | AE44: 0 | AF44: 0 | AG44: 0
B45: Аутсорсинговые услуги | C45: 0 | D45: 0 | K45: 15000 | L45: 15125.26 | M45: 17999.059 | N45: 21418.88 | O45: 25488.468 | P45: 30331.276 | Q45: 36094.219 | S45: 0 | T45: 0 | U45: 0 | V45: 0 | W45: 0 | X45: 0 | Y45: 0 | AA45: 0 | AB45: 0 | AC45: 0 | AD45: 0 | AE45: 0 | AF45: 0 | AG45: 0
B46: Комиссии трейдинговой площадки | C46: 0 | D46: 0 | K46: 0 | L46: 0 | M46: 0 | N46: 0 | O46: 0 | P46: 0 | Q46: 0 | S46: 23700 | T46: 24565 | U46: 29797.345 | V46: 37246.681 | W46: 47675.752 | X46: 63408.75 | Y46: 85601.813 | AA46: 0 | AB46: 0 | AC46: 0 | AD46: 0 | AE46: 0 | AF46: 0 | AG46: 0
...

Sheet Консолидация--->

Sheet ОДДС
A1: ОДДС, тыс. руб. | B1: Консолидация по группе | AV1: А | BD1: Б | BL1: В | BT1: Г
B2: 2025 план | C2: ВГО 1 | D2: ВГО 2 | E2: ВГО 3 | F2: ВГО 4 | G2: ВГО 5 | H2: А--->В беспроцентный заём | I2: 2025 факт | J2: ВГО 1 | K2: ВГО 2 | L2: ВГО 3 | M2: ВГО 4 | N2: ВГО 5 | O2: А--->В беспроцентный заём | P2: 2026 | Q2: ВГО 1 | R2: ВГО 2 | S2: ВГО 3 | T2: ВГО 4 | U2: ВГО 5 | V2: А--->В беспроцентный заём | W2: 2027 | X2: ВГО 1 | Y2: ВГО 2 | Z2: ВГО 3 | AA2: ВГО 4 | AB2: ВГО 5 | AC2: 2028 | AD2: ВГО 1 | AE2: ВГО 2 | AF2: ВГО 3 | AG2: ВГО 4 | AH2: ВГО 5 | AI2: 2029 | AJ2: ВГО 1 | AK2: ВГО 2 | AL2: ВГО 3 | AM2: ВГО 4 | AN2: ВГО 5 | AO2: 2030 | AP2: ВГО 1 | AQ2: ВГО 2 | AR2: ВГО 3 | AS2: ВГО 4 | AT2: ВГО 5 | AV2: 2025 план | AW2: 2025 факт | AX2: 2026 | AY2: 2027 | AZ2: 2028 | BA2: 2029 | BB2: 2030 | BD2: 2025 план | BE2: 2025 факт | BF2: 2026 | BG2: 2027 | BH2: 2028 | BI2: 2029 | BJ2: 2030 | BL2: 2025 план | BM2: 2025 факт | BN2: 2026 | BO2: 2027 | BP2: 2028 | BQ2: 2029 | BR2: 2030 | BT2: 2025 план | BU2: 2025 факт | BV2: 2026 | BW2: 2027 | BX2: 2028 | BY2: 2029 | BZ2: 2030
A3: Остаток денежных средств на начало периода | B3: =(AV3+BD3+BL3) -> 1073.4 | I3: =(AW3+BE3+BM3) -> 1122.4891 | P3: =(AX3+BF3+BN3) -> 22519.308 | W3: =(AY3+BG3+BO3) -> 35338.17 | AC3: =(AZ3+BH3+BP3) -> 54214.769 | AI3: =BA3+BI3+BQ3 -> 74124.687 | AO3: =BB3+BJ3+BR3 -> 92077.029 | AV3: 9 | AW3: 662.6 | AX3: 8742.35 | AY3: 10673.443 | AZ3: 13253.576 | BA3: 15782.006 | BB3: 17305.874 | BD3: 791.2 | BE3: 419.68907 | BF3: =BE35 -> 12536.758 | BG3: =BF35 -> 20000.7 | BH3: =BG35 -> 27453.85 | BI3: =BH35 -> 33764.424 | BJ3: =BI35 -> 39974.694 | BL3: 273.2 | BM3: 40.2 | BN3: =BM35 -> 1240.2 | BO3: =BN35 -> 4664.0262 | BP3: =BO35 -> 13507.343 | BQ3: =BP35 -> 24578.257 | BR3: =BQ35 -> 34796.461 | BT3: 144 | BU3: 444.03722 | BV3: =BU35 -> 2946.3509 | BW3: =BV35 -> 5721.2682 | BX3: =BW35 -> 9039.1932 | BY3: =BX35 -> 12981.224 | BZ3: =BY35 -> 17639.033
A5: Текущая (операционная) деятельность:
A6: Поступления, всего: | B6: =SUM(B7:B12) -> 128086 | I6: =SUM(I7:I12) -> 127089.48 | P6: =SUM(P7:P12) -> 139348.29 | W6: =SUM(W7:W12) -> 166396.81 | AC6: =SUM(AC7:AC12) -> 198987.23 | AI6: =SUM(AI7:AI12) -> 239790.38 | AO6: =SUM(AO7:AO12) -> 290819.46 | AV6: 55700 | AW6: 53772 | AX6: 59613.237 | AY6: 68637.137 | AZ6: 79030.195 | BA6: 91000.325 | BB6: 104787.03 | BD6: =SUM(BD7:BD12) -> 49950 | BE6: =SUM(BE7:BE12) -> 50718.476 | BF6: =SUM(BF7:BF12) -> 52086.33 | BG6: =SUM(BG7:BG12) -> 61557.058 | BH6: =SUM(BH7:BH12) -> 72759.421 | BI6: =SUM(BI7:BI12) -> 86010.948 | BJ6: =SUM(BJ7:BJ12) -> 101687.49 | BL6: =SUM(BL7:BL12) -> 24955 | BM6: =SUM(BM7:BM12) -> 25118 | BN6: =SUM(BN7:BN12) -> 30405.325 | BO6: =SUM(BO7:BO12) -> 39086.87 | BP6: =SUM(BP7:BP12) -> 50209.58 | BQ6: =SUM(BQ7:BQ12) -> 65918.85 | BR6: =SUM(BR7:BR12) -> 87612.519 | BT6: =SUM(BT7:BT12) -> 10010 | BU6: =SUM(BU7:BU12) -> 9266.6576 | BV6: =SUM(BV7:BV12) -> 9888.7311 | BW6: =SUM(BW7:BW12) -> 10967.44 | BX6: =SUM(BX7:BX12) -> 12177.162 | BY6: =SUM(BY7:BY12) -> 13533.812 | BZ6: =SUM(BZ7:BZ12) -> 15055.24
A7: Денежные средства, полученные за обработку платежей и переводов | B7: =(AV7+BD7+BL7)+SUM(C7:H7) -> 51318 | C7: =-Вводные!C23 -> -110 | F7: =-Вводные!C26 -> -22 | I7: =(AW7+BE7+BM7)+SUM(J7:O7) -> 51370 | J7: =-Вводные!D23 -> -110 | M7: =-Вводные!D26 -> -22 | P7: =(AX7+BF7+BN7)+SUM(Q7:U7) -> 59184.837 | Q7: =-Вводные!E23 -> -115.5 | T7: =-Вводные!E26 -> -23.1 | W7: =(AY7+BG7+BO7)+SUM(X7:AB7) -> 68187.592 | X7: =-Вводные!F23 -> -121 | AA7: =-Вводные!F26 -> -24.255 | AC7: =(AZ7+BH7+BP7)+SUM(AD7:AH7) -> 78558.722 | AD7: =-Вводные!G23 -> -126.5 | AG7: =-Вводные!G26 -> -25.46775 | AI7: =(BA7+BI7+BQ7)+SUM(AJ7:AN7) -> 90506.104 | AJ7: =-Вводные!H23 -> -132 | AM7: =-Вводные!H26 -> -26.741138 | AO7: =(BB7+BJ7+BR7)+SUM(AP7:AT7) -> 104269.19 | AP7: =-Вводные!I23 -> -137.5 | AS7: =-Вводные!I26 -> -28.078194 | AV7: 51450 | AW7: 51502 | AX7: 59323.437 | AY7: 68332.847 | AZ7: 78710.69 | BA7: 90664.845 | BB7: 104434.77 | BD7: 0 | BE7: 0 | BF7: 0 | BG7: 0 | BH7: 0 | BI7: 0 | BJ7: 0 | BL7: 0 | BM7: 0 | BN7: 0 | BO7: 0 | BP7: 0 | BQ7: 0 | BR7: 0 | BT7: 0 | BU7: 0 | BV7: 0 | BW7: 0 | BX7: 0 | BY7: 0 | BZ7: 0
A8: Денежные средства, полученные за разработку программного обеспечения | B8: =(AV8+BD8+BL8)+SUM(C8:H8) -> 26290 | G8: =-Вводные!C27 -> -1210 | I8: =(AW8+BE8+BM8)+SUM(J8:O8) -> 26879.768 | N8: =-Вводные!D27 -> -1210 | P8: =(AX8+BF8+BN8)+SUM(Q8:U8) -> 31825.926 | U8: =-Вводные!E27 -> -1320 | W8: =(AY8+BG8+BO8)+SUM(X8:AB8) -> 37792.193 | AB8: =-Вводные!F27 -> -1320 | AC8: =(AZ8+BH8+BP8)+SUM(AD8:AH8) -> 44832.388 | AH8: =-Вводные!G27 -> -1320 | AI8: =(BA8+BI8+BQ8)+SUM(AJ8:AN8) -> 53139.818 | AN8: =-Вводные!H27 -> -1320 | AO8: =(BB8+BJ8+BR8)+SUM(AP8:AT8) -> 62942.585 | AT8: =-Вводные!I27 -> -1320 | AV8: 0 | AW8: 0 | AX8: 0 | AY8: 0 | AZ8: 0 | BA8: 0 | BB8: 0 | BD8: 27500 | BE8: 28089.768 | BF8: 33145.926 | BG8: 39112.193 | BH8: 46152.388 | BI8: 54459.818 | BJ8: 64262.585 | BL8: 0 | BM8: 0 | BN8: 0 | BO8: 0 | BP8: 0 | BQ8: 0 | BR8: 0 | BT8: 0 | BU8: 0 | BV8: 0 | BW8: 0 | BX8: 0 | BY8: 0 | BZ8: 0
A9: Денежные средства, полученные от аутсорсинговых услуг | B9: =(AV9+BD9+BL9)+SUM(C9:H9) -> 13823 | D9: =-Вводные!C24 -> -1100 | E9: =-Вводные!C25 -> -77 | I9: =(AW9+BE9+BM9)+SUM(J9:O9) -> 13948.26 | K9: =-Вводные!D24 -> -1100 | L9: =-Вводные!D25 -> -77 | P9: =(AX9+BF9+BN9)+SUM(Q9:U9) -> 16701.059 | R9: =-Вводные!E24 -> -1210 | S9: =-Вводные!E25 -> -88 | W9: =(AY9+BG9+BO9)+SUM(X9:AB9) -> 19999.88 | Y9: =-Вводные!F24 -> -1320 | Z9: =-Вводные!F25 -> -99 | AC9: =(AZ9+BH9+BP9)+SUM(AD9:AH9) -> 23948.468 | AE9: =-Вводные!G24 -> -1430 | AF9: =-Вводные!G25 -> -110 | AI9: =(BA9+BI9+BQ9)+SUM(AJ9:AN9) -> 28670.276 | AK9: =-Вводные!H24 -> -1540 | AL9: =-Вводные!H25 -> -121 | AO9: =(BB9+BJ9+BR9)+SUM(AP9:AT9) -> 34312.219 | AQ9: =-Вводные!I24 -> -1650 | AR9: =-Вводные!I25 -> -132 | AV9: 0 | AW9: 0 | AX9: 0 | AY9: 0 | AZ9: 0 | BA9: 0 | BB9: 0 | BD9: 15000 | BE9: 15125.26 | BF9: 17999.059 | BG9: 21418.88 | BH9: 25488.468 | BI9: 30331.276 | BJ9: 36094.219 | BL9: 0 | BM9: 0 | BN9: 0 | BO9: 0 | BP9: 0 | BQ9: 0 | BR9: 0 | BT9: 0 | BU9: 0 | BV9: 0 | BW9: 0 | BX9: 0 | BY9: 0 | BZ9: 0
A10: Денежные средства, полученные за услуги трейдинговой площадки | B10: =(AV10+BD10+BL10) -> 23700 | I10: =(AW10+BE10+BM10) -> 24565 | P10: =(AX10+BF10+BN10) -> 29797.345 | W10: =(AY10+BG10+BO10) -> 37246.681 | AC10: =(AZ10+BH10+BP10) -> 47675.752 | AI10: =BA10+BI10+BQ10 -> 63408.75 | AO10: =BB10+BJ10+BR10 -> 85601.813 | AV10: 0 | AW10: 0 | AX10: 0 | AY10: 0 | AZ10: 0 | BA10: 0 | BB10: 0 | BD10: 0 | BE10: 0 | BF10: 0 | BG10: 0 | BH10: 0 | BI10: 0 | BJ10: 0 | BL10: 23700 | BM10: 24565 | BN10: 29797.345 | BO10: 37246.681 | BP10: 47675.752 | BQ10: 63408.75 | BR10: 85601.813 | BT10: 0 | BU10: 0 | BV10: 0 | BW10: 0 | BX10: 0 | BY10: 0 | BZ10: 0
A11: Денежные средства, полученные за услуги бронирования | B11: =(AV11+BD11+BL11) -> 0 | I11: =(AW11+BE11+BM11) -> 0 | P11: =(AX11+BF11+BN11) -> 0 | W11: =(AY11+BG11+BO11) -> 0 | AC11: =(AZ11+BH11+BP11) -> 0 | AI11: =BA11+BI11+BQ11 -> 0 | AO11: =BB11+BJ11+BR11 -> 0 | AV11: 0 | AW11: 0 | AX11: 0 | AY11: 0 | AZ11: 0 | BA11: 0 | BB11: 0 | BD11: 0 | BE11: 0 | BF11: 0 | BG11: 0 | BH11: 0 | BI11: 0 | BJ11: 0 | BL11: 0 | BM11: 0 | BN11: 0 | BO11: 0 | BP11: 0 | BQ11: 0 | BR11: 0 | BT11: 8500 | BU11: 7911.8422 | BV11: 8873.1311 | BW11: 9951.2165 | BX11: 11160.289 | BY11: 12516.264 | BZ11: 14036.991
A12: Прочие расчёты с контрагентами | B12: =(AV12+BD12+BL12) -> 12955 | I12: =(AW12+BE12+BM12) -> 10326.448 | P12: =(AX12+BF12+BN12) -> 1839.1248 | W12: =(AY12+BG12+BO12) -> 3170.4631 | AC12: =(AZ12+BH12+BP12) -> 3971.8981 | AI12: =BA12+BI12+BQ12 -> 4065.4334 | AO12: =BB12+BJ12+BR12 -> 3693.6494 | AV12: 4250 | AW12: 2270 | AX12: 289.8 | AY12: 304.29 | AZ12: 319.5045 | BA12: 335.47973 | BB12: 352.25371 | BD12: 7450 | BE12: 7503.4483 | BF12: 941.34483 | BG12: 1025.9843 | BH12: 1118.5655 | BI12: 1219.8539 | BJ12: 1330.6899 | BL12: 1255 | BM12: 553 | BN12: 607.98 | BO12: 1840.1888 | BP12: 2533.8281 | BQ12: 2510.0998 | BR12: 2010.7058 | BT12: 1510 | BU12: 1354.8153 | BV12: 1015.6 | BW12: 1016.224 | BX12: 1016.873 | BY12: 1017.5479 | BZ12: 1018.2498
A13: Выбытия, всего: | B13: =SUM(B14:B17) -> -92192.25 | I13: =SUM(I14:I17) -> -93669.665 | P13: =SUM(P14:P17) -> -102387.53 | W13: =SUM(W14:W17) -> -116457.9 | AC13: =SUM(AC14:AC17) -> -132882.75 | AI13: =SUM(AI14:AI17) -> -152504.01 | AO13: =SUM(AO14:AO17) -> -176037.01 | AV13: -34004 | AW13: -34332.417 | AX13: -40279.119 | AY13: -45213.628 | AZ13: -50610.769 | BA13: -56535.462 | BB13: -63046.011 | BD13: =SUM(BD14:BD17) -> -37981.25 | BE13: =SUM(BE14:BE17) -> -38292.249 | BF13: =SUM(BF14:BF17) -> -38270.448 | BG13: =SUM(BG14:BG17) -> -43706.831 | BH13: =SUM(BH14:BH17) -> -50004.152 | BI13: =SUM(BI14:BI17) -> -57305.744 | BJ13: =SUM(BJ14:BJ17) -> -65779.409 | BL13: =SUM(BL14:BL17) -> -22726 | BM13: =SUM(BM14:BM17) -> -23564 | BN13: =SUM(BN14:BN17) -> -26594.559 | BO13: =SUM(BO14:BO17) -> -30421.697 | BP13: =SUM(BP14:BP17) -> -35279.798 | BQ13: =SUM(BQ14:BQ17) -> -41802.546 | BR13: =SUM(BR14:BR17) -> -50479.167 | BT13: =SUM(BT14:BT17) -> -6614.25 | BU13: =SUM(BU14:BU17) -> -6564.3439 | BV13: =SUM(BV14:BV17) -> -6905.8137 | BW13: =SUM(BW14:BW17) -> -7433.1955 | BX13: =SUM(BX14:BX17) -> -8010.1589 | BY13: =SUM(BY14:BY17) -> -8642.0314 | BZ13: =SUM(BZ14:BZ17) -> -9334.7529
A14: Расчёты с персоналом | B14: =(AV14+BD14+BL14) -> -57760 | I14: =(AW14+BE14+BM14) -> -57971.647 | P14: =(AX14+BF14+BN14) -> -64524.393 | W14: =(AY14+BG14+BO14) -> -71691.614 | AC14: =(AZ14+BH14+BP14) -> -79542.964 | AI14: =BA14+BI14+BQ14 -> -88157.166 | AO14: =BB14+BJ14+BR14 -> -97623.289 | AV14: -21110 | AW14: -21096.08 | AX14: -23921.845 | AY14: -26917.155 | AZ14: -30092.185 | BA14: -33457.716 | BB14: -37025.179 | BD14: -20600 | BE14: -20620.567 | BF14: -23345.098 | BG14: -26452.511 | BH14: -29998.431 | BI14: -34046.701 | BJ14: -38670.608 | BL14: -16050 | BM14: -16255 | BN14: -17257.45 | BO14: -18321.947 | BP14: -19452.348 | BQ14: -20652.749 | BR14: -21927.502 | BT14: -4980 | BU14: -5012.7578 | BV14: -5238.3319 | BW14: -5474.0568 | BX14: -5720.3894 | BY14: -5977.8069 | BZ14: -6246.8082
A15: Оплата маркетинговых и коммерческих расходов | B15: =(AV15+BD15+BL15) -> -15000 | I15: =(AW15+BE15+BM15) -> -15338.189 | P15: =(AX15+BF15+BN15) -> -17073.35 | W15: =(AY15+BG15+BO15) -> -18740.989 | AC15: =(AZ15+BH15+BP15) -> -20593.794 | AI15: =BA15+BI15+BQ15 -> -22654.071 | AO15: =BB15+BJ15+BR15 -> -25129.228 | AV15: -3800 | AW15: -3767 | AX15: -4278.245 | AY15: -4548.9038 | AZ15: -4803.1085 | BA15: -5029.617 | BB15: -5214.1513 | BD15: -6800 | BE15: -6871.1894 | BF15: -7249.1048 | BG15: -7647.8056 | BH15: -8068.4349 | BI15: -8512.1988 | BJ15: -8980.3698 | BL15: -4400 | BM15: -4700 | BN15: -5546 | BO15: -6544.28 | BP15: -7722.2504 | BQ15: -9112.2555 | BR15: -10934.707 | BT15: -360 | BU15: -366.66667 | BV15: -399.66667 | BW15: -435.63667 | BX15: -474.84397 | BY15: -517.57992 | BZ15: -564.16212
A16: Уплаченный налог на прибыль | B16: =(AV16+BD16+BL16) -> -2680.25 | I16: =(AW16+BE16+BM16) -> -3125.7003 | P16: =(AX16+BF16+BN16) -> -10050.153 | W16: =(AY16+BG16+BO16) -> -13836.113 | AC16: =(AZ16+BH16+BP16) -> -18837.906 | AI16: =BA16+BI16+BQ16 -> -25741.153 | AO16: =BB16+BJ16+BR16 -> -34897.252 | AV16: -686 | AW16: -971.25 | AX16: -5741.5578 | AY16: -7087.4789 | AZ16: -8716.8078 | BA16: -10694.122 | BB16: -13079.729 | BD16: -1795.25 | BE16: -1945.4503 | BF16: -3389.046 | BG16: -4646.4689 | BH16: -6188.2129 | BI16: -8071.9078 | BJ16: -10366.436 | BL16: -199 | BM16: -209 | BN16: -919.54875 | BO16: -2102.1654 | BP16: -3932.8853 | BQ16: -6975.1228 | BR16: -11451.087 | BT16: -551.25 | BU16: -387.32667 | BV16: -542.5409 | BW16: -721.5795 | BX16: -927.57224 | BY16: -1164.0409 | BZ16: -1434.9477
A17: Прочие расчёты с контрагентами | B17: =(AV17+BD17+BL17)+SUM(C17:H17) -> -16752 | C17: =Вводные!C23 -> 110 | D17: =Вводные!C24 -> 1100 | E17: =Вводные!C25 -> 77 | F17: =Вводные!C26 -> 22 | G17: =Вводные!C27 -> 1210 | I17: =(AW17+BE17+BM17)+SUM(J17:O17) -> -17234.129 | J17: =Вводные!C23 -> 110 | K17: =Вводные!C24 -> 1100 | L17: =Вводные!C25 -> 77 | M17: =Вводные!D26 -> 22 | N17: =Вводные!D27 -> 1210 | P17: =(AX17+BF17+BN17)+SUM(Q17:U17) -> -10739.63 | Q17: =Вводные!E23 -> 115.5 | R17: =Вводные!E24 -> 1210 | S17: =Вводные!E25 -> 88 | T17: =Вводные!E26 -> 23.1 | U17: =Вводные!E27 -> 1320 | W17: =(AY17+BG17+BO17)+SUM(X17:AB17) -> -12189.184 | X17: =Вводные!F23 -> 121 | Y17: =Вводные!F24 -> 1320 | Z17: =Вводные!F25 -> 99 | AA17: =Вводные!F26 -> 24.255 | AB17: =Вводные!F27 -> 1320 | AC17: =(AZ17+BH17+BP17)+SUM(AD17:AH17) -> -13908.088 | AD17: =Вводные!G23 -> 126.5 | AE17: =Вводные!G24 -> 1430 | AF17: =Вводные!G25 -> 110 | AG17: =Вводные!G26 -> 25.46775 | AH17: =Вводные!G27 -> 1320 | AI17: =(BA17+BI17+BQ17)+SUM(AJ17:AN17) -> -15951.621 | AJ17: =Вводные!H23 -> 132 | AK17: =Вводные!H24 -> 1540 | AL17: =Вводные!H25 -> 121 | AM17: =Вводные!H26 -> 26.741138 | AN17: =Вводные!H27 -> 1320 | AO17: =(BB17+BJ17+BR17)+SUM(AP17:AT17) -> -18387.239 | AP17: =Вводные!I23 -> 137.5 | AQ17: =Вводные!I24 -> 1650 | AR17: =Вводные!I25 -> 132 | AS17: =Вводные!I26 -> 28.078194 | AT17: =Вводные!I27 -> 1320 | AV17: -8408 | AW17: -8498.0867 | AX17: -6337.471 | AY17: -6660.0902 | AZ17: -6998.6679 | BA17: -7354.0074 | BB17: -7726.9516 | BD17: -8786 | BE17: -8855.042 | BF17: -4287.1986 | BG17: -4960.0456 | BH17: -5749.0732 | BI17: -6674.9363 | BJ17: -7761.9951 | BL17: -2077 | BM17: -2400 | BN17: -2871.56 | BO17: -3453.3036 | BP17: -4172.3143 | BQ17: -5062.4188 | BR17: -6165.871 | BT17: -723 | BU17: -797.59278 | BV17: -725.27427 | BW17: -801.92257 | BX17: -887.35329 | BY17: -982.60369 | BZ17: -1088.8349
A18: Сальдо денежных средств по текущей деятельности: | B18: =B6+B13 -> 35893.75 | I18: =I6+I13 -> 33419.811 | P18: =P6+P13 -> 36960.767 | W18: =W6+W13 -> 49938.909 | AC18: =AC6+AC13 -> 66104.477 | AI18: =AI6+AI13 -> 87286.37 | AO18: =AO6+AO13 -> 114782.45 | AV18: 21696 | AW18: 19439.583 | AX18: 19334.118 | AY18: 23423.508 | AZ18: 28419.426 | BA18: 34464.862 | BB18: 41741.015 | BD18: =BD6+BD13 -> 11968.75 | BE18: =BE6+BE13 -> 12426.228 | BF18: =BF6+BF13 -> 13815.883 | BG18: =BG6+BG13 -> 17850.227 | BH18: =BH6+BH13 -> 22755.269 | BI18: =BI6+BI13 -> 28705.204 | BJ18: =BJ6+BJ13 -> 35908.085 | BL18: =BL6+BL13 -> 2229 | BM18: =BM6+BM13 -> 1554 | BN18: =BN6+BN13 -> 3810.7662 | BO18: =BO6+BO13 -> 8665.1735 | BP18: =BP6+BP13 -> 14929.782 | BQ18: =BQ6+BQ13 -> 24116.304 | BR18: =BR6+BR13 -> 37133.352 | BT18: =BT6+BT13 -> 3395.75 | BU18: =BU6+BU13 -> 2702.3137 | BV18: =BV6+BV13 -> 2982.9173 | BW18: =BW6+BW13 -> 3534.2449 | BX18: =BX6+BX13 -> 4167.0034 | BY18: =BY6+BY13 -> 4891.7809 | BZ18: =BZ6+BZ13 -> 5720.4875
A20: Инвестиционная деятельность: | AI20: =BA20+BI20+BQ20 -> 0 | AO20: =BB20+BJ20+BR20 -> 0
A21: Дивиденды полученные | B21: =(AV21+BD21+BL21) -> 1373 | I21: =(AW21+BE21+BM21) -> 1372.7123 | P21: =(AX21+BF21+BN21) -> 1372.7123 | W21: =(AY21+BG21+BO21) -> 1372.7123 | AC21: =AZ21+BH21+BP21 -> 1372.7123 | AI21: =BA21+BI21+BQ21 -> 1372.7123 | AO21: =BB21+BJ21+BR21 -> 1372.7123 | AV21: 109 | AW21: 109 | AX21: 109 | AY21: 109 | AZ21: 109 | BA21: 109 | BB21: 109 | BD21: 469 | BE21: 468.71228 | BF21: 468.71228 | BG21: 468.71228 | BH21: 468.71228 | BI21: 468.71228 | BJ21: 468.71228 | BL21: 795 | BM21: 795 | BN21: 795 | BO21: 795 | BP21: 795 | BQ21: 795 | BR21: 795 | BT21: 0 | BU21: 0 | BV21: 0 | BW21: 0 | BX21: 0 | BY21: 0 | BZ21: 0
A22: Проценты полученные | B22: =(AV22+BD22+BL22) -> 0 | I22: =(AW22+BE22+BM22) -> 0 | P22: =(AX22+BF22+BN22) -> 0 | W22: =(AY22+BG22+BO22) -> 0 | AC22: =AZ22+BH22+BP22 -> 0 | AI22: =BA22+BI22+BQ22 -> 0 | AO22: =BB22+BJ22+BR22 -> 0 | AV22: 0 | AW22: 0 | AX22: 0 | AY22: 0 | AZ22: 0 | BA22: 0 | BB22: 0 | BD22: 0 | BE22: 0 | BF22: 0 | BG22: 0 | BH22: 0 | BI22: 0 | BJ22: 0 | BL22: 0 | BM22: 0 | BN22: 0 | BO22: 0 | BP22: 0 | BQ22: 0 | BR22: 0 | BT22: 0 | BU22: 0 | BV22: 0 | BW22: 0 | BX22: 0 | BY22: 0 | BZ22: 0
A23: Проценты уплаченные | B23: =(AV23+BD23+BL23) -> -51 | I23: =(AW23+BE23+BM23) -> -51 | P23: =(AX23+BF23+BN23) -> -51 | W23: =(AY23+BG23+BO23) -> 0 | AC23: =AZ23+BH23+BP23 -> 0 | AI23: =BA23+BI23+BQ23 -> 0 | AO23: =BB23+BJ23+BR23 -> 0 | AV23: -51 | AW23: -51 | AX23: -51 | AY23: 0 | AZ23: 0 | BA23: 0 | BB23: 0 | BD23: 0 | BE23: 0 | BF23: 0 | BG23: 0 | BH23: 0 | BI23: 0 | BJ23: 0 | BL23: 0 | BM23: 0 | BN23: 0 | BO23: 0 | BP23: 0 | BQ23: 0 | BR23: 0 | BT23: 0 | BU23: 0 | BV23: 0 | BW23: 0 | BX23: 0 | BY23: 0 | BZ23: 0
A24: Сальдо денежных средств по инвестиционной деятельности: | B24: =SUM(B21:B23) -> 1322 | I24: =SUM(I21:I23) -> 1321.7123 | P24: =SUM(P21:P23) -> 1321.7123 | W24: =SUM(W21:W23) -> 1372.7123 | AC24: =SUM(AC21:AC23) -> 1372.7123 | AI24: =SUM(AI20:AI23) -> 1372.7123 | AO24: =SUM(AO20:AO23) -> 1372.7123 | AV24: 58 | AW24: 58 | AX24: 58 | AY24: 109 | AZ24: 109 | BA24: 109 | BB24: 109 | BD24: =SUM(BD21:BD23) -> 469 | BE24: =SUM(BE21:BE23) -> 468.71228 | BF24: =SUM(BF21:BF23) -> 468.71228 | BG24: =SUM(BG21:BG23) -> 468.71228 | BH24: =SUM(BH21:BH23) -> 468.71228 | BI24: =SUM(BI21:BI23) -> 468.71228 | BJ24: =SUM(BJ21:BJ23) -> 468.71228 | BL24: =SUM(BL21:BL23) -> 795 | BM24: =SUM(BM21:BM23) -> 795 | BN24: =SUM(BN21:BN23) -> 795 | BO24: =SUM(BO21:BO23) -> 795 | BP24: =SUM(BP21:BP23) -> 795 | BQ24: =SUM(BQ21:BQ23) -> 795 | BR24: =SUM(BR21:BR23) -> 795 | BT24: =SUM(BT21:BT23) -> 0 | BU24: =SUM(BU21:BU23) -> 0 | BV24: =SUM(BV21:BV23) -> 0 | BW24: =SUM(BW21:BW23) -> 0 | BX24: =SUM(BX21:BX23) -> 0 | BY24: =SUM(BY21:BY23) -> 0 | BZ24: =SUM(BZ21:BZ23) -> 0
A27: Финансовая деятельность:
A28: Денежные средства, полученные по кредиту (тело) | B28: =(AV28+BD28+BL28)+H28 -> 0 | H28: =-Вводные!C32 -> -600 | I28: =(AW28+BE28+BM28)+O28 -> 0 | O28: =-Вводные!D33 -> -600 | P28: =(AX28+BF28+BN28)+V28 -> 0 | V28: =-Вводные!E32 -> -600 | W28: =(AY28+BG28+BO28) -> 0 | AC28: =AZ28+BH28+BP28 -> 0 | AI28: =BA28+BI28+BQ28 -> 0 | AO28: =BB28+BJ28+BR28 -> 0 | AV28: 600 | AW28: 600 | AX28: 600 | AY28: 0 | AZ28: 0 | BA28: 0 | BB28: 0 | BD28: 0 | BE28: 0 | BF28: 0 | BG28: 0 | BH28: 0 | BI28: 0 | BJ28: 0 | BL28: 0 | BM28: 0 | BN28: 0 | BO28: 0 | BP28: 0 | BQ28: 0 | BR28: 0 | BT28: 0 | BU28: 0 | BV28: 0 | BW28: 0 | BX28: 0 | BY28: 0 | BZ28: 0
A29: Денежные средства, уплаченные за аренду | B29: =(AV29+BD29+BL29) -> -2191 | I29: =(AW29+BE29+BM29) -> -2190.7038 | P29: =(AX29+BF29+BN29) -> -2309.6184 | W29: =(AY29+BG29+BO29) -> -2435.022 | AC29: =AZ29+BH29+BP29 -> -2567.2706 | AI29: =BA29+BI29+BQ29 -> -2706.7398 | AO29: =BB29+BJ29+BR29 -> -2853.826 | AV29: -864 | AW29: -863.83333 | AX29: -907.025 | AY29: -952.37625 | AZ29: -999.99506 | BA29: -1049.9948 | BB29: -1102.4946 | BD29: -778 | BE29: -777.8705 | BF29: -820.65338 | BG29: -865.78931 | BH29: -913.40773 | BI29: -963.64515 | BJ29: -1016.6456 | BL29: -549 | BM29: -549 | BN29: -581.94 | BO29: -616.8564 | BP29: -653.86778 | BQ29: -693.09985 | BR29: -734.68584 | BT29: -200 | BU29: -200 | BV29: -208 | BW29: -216.32 | BX29: -224.9728 | BY29: -233.97171 | BZ29: -243.33058
A30: Денежные средства, уплаченные по кредиту (тело) | B30: =(AV30+BD30+BL30)+H30 -> -1154 | H30: =Вводные!C33 -> 600 | I30: =(AW30+BE30+BM30)+O30 -> -1154 | O30: =Вводные!D32 -> 600 | P30: =(AX30+BF30+BN30)+V30 -> -1154 | V30: =Вводные!E32 -> 600 | W30: =(AY30+BG30+BO30) -> 0 | AC30: =AZ30+BH30+BP30 -> 0 | AI30: =BA30+BI30+BQ30 -> 0 | AO30: =BB30+BJ30+BR30 -> 0 | AV30: -1154 | AW30: -1154 | AX30: -1154 | AY30: 0 | AZ30: 0 | BA30: 0 | BB30: 0 | BD30: 0 | BE30: 0 | BF30: 0 | BG30: 0 | BH30: 0 | BI30: 0 | BJ30: 0 | BL30: -600 | BM30: -600 | BN30: -600 | BO30: 0 | BP30: 0 | BQ30: 0 | BR30: 0 | BT30: 0 | BU30: 0 | BV30: 0 | BW30: 0 | BX30: 0 | BY30: 0 | BZ30: 0
A31: Денежные средства, уплаченные в качестве дивидендов | B31: =(AV31+BD31+BL31) -> -7000 | I31: =(AW31+BE31+BM31) -> -10000 | P31: =(AX31+BF31+BN31) -> -22000 | W31: =(AY31+BG31+BO31) -> -30000 | AC31: =AZ31+BH31+BP31 -> -45000 | AI31: =BA31+BI31+BQ31 -> -68000 | AO31: =BB31+BJ31+BR31 -> -97000 | AV31: -7000 | AW31: -10000 | AX31: -16000 | AY31: -20000 | AZ31: -25000 | BA31: -32000 | BB31: -39000 | BD31: 0 | BE31: 0 | BF31: -6000 | BG31: -10000 | BH31: -16000 | BI31: -22000 | BJ31: -29000 | BL31: 0 | BM31: 0 | BN31: 0 | BO31: 0 | BP31: -4000 | BQ31: -14000 | BR31: -29000 | BT31: 0 | BU31: 0 | BV31: 0 | BW31: 0 | BX31: 0 | BY31: 0 | BZ31: -1000
A32: Сальдо денежных средств по финансовой деятельности: | B32: =SUM(B28:B31) -> -10345 | I32: =SUM(I28:I31) -> -13344.704 | P32: =SUM(P28:P31) -> -25463.618 | W32: =SUM(W28:W31) -> -32435.022 | AC32: =SUM(AC28:AC31) -> -47567.271 | AI32: =SUM(AI28:AI31) -> -70706.74 | AO32: =SUM(AO28:AO31) -> -99853.826 | AV32: -8418 | AW32: -11417.833 | AX32: -17461.025 | AY32: -20952.376 | AZ32: -25999.995 | BA32: -33049.995 | BB32: -40102.495 | BD32: =SUM(BD28:BD31) -> -778 | BE32: =SUM(BE28:BE31) -> -777.8705 | BF32: =SUM(BF28:BF31) -> -6820.6534 | BG32: =SUM(BG28:BG31) -> -10865.789 | BH32: =SUM(BH28:BH31) -> -16913.408 | BI32: =SUM(BI28:BI31) -> -22963.645 | BJ32: =SUM(BJ28:BJ31) -> -30016.646 | BL32: =SUM(BL28:BL31) -> -1149 | BM32: =SUM(BM28:BM31) -> -1149 | BN32: =SUM(BN28:BN31) -> -1181.94 | BO32: =SUM(BO28:BO31) -> -616.8564 | BP32: =SUM(BP28:BP31) -> -4653.8678 | BQ32: =SUM(BQ28:BQ31) -> -14693.1 | BR32: =SUM(BR28:BR31) -> -29734.686 | BT32: =SUM(BT28:BT31) -> -200 | BU32: =SUM(BU28:BU31) -> -200 | BV32: =SUM(BV28:BV31) -> -208 | BW32: =SUM(BW28:BW31) -> -216.32 | BX32: =SUM(BX28:BX31) -> -224.9728 | BY32: =SUM(BY28:BY31) -> -233.97171 | BZ32: =SUM(BZ28:BZ31) -> -1243.3306
A33: Денежный поток, итого | B33: =B18+B24+B32 -> 26870.75 | I33: =I18+I24+I32 -> 21396.819 | P33: =P18+P24+P32 -> 12818.861 | W33: =W18+W24+W32 -> 18876.599 | AC33: =AC18+AC24+AC32 -> 19909.918 | AI33: =AI18+AI24+AI32 -> 17952.342 | AO33: =AO18+AO24+AO32 -> 16301.338 | AV33: 13336 | AW33: 8079.75 | AX33: 1931.0934 | AY33: 2580.1321 | AZ33: 2528.4305 | BA33: 1523.8676 | BB33: 1747.5206 | BD33: =BD18+BD24+BD32 -> 11659.75 | BE33: =BE18+BE24+BE32 -> 12117.069 | BF33: =BF18+BF24+BF32 -> 7463.9414 | BG33: =BG18+BG24+BG32 -> 7453.1498 | BH33: =BH18+BH24+BH32 -> 6310.5739 | BI33: =BI18+BI24+BI32 -> 6210.2708 | BJ33: =BJ18+BJ24+BJ32 -> 6360.1518 | BL33: =BL18+BL24+BL32 -> 1875 | BM33: =BM18+BM24+BM32 -> 1200 | BN33: =BN18+BN24+BN32 -> 3423.8262 | BO33: =BO18+BO24+BO32 -> 8843.3171 | BP33: =BP18+BP24+BP32 -> 11070.914 | BQ33: =BQ18+BQ24+BQ32 -> 10218.204 | BR33: =BR18+BR24+BR32 -> 8193.6661 | BT33: =BT18+BT24+BT32 -> 3195.75 | BU33: =BU18+BU24+BU32 -> 2502.3137 | BV33: =BV18+BV24+BV32 -> 2774.9173 | BW33: =BW18+BW24+BW32 -> 3317.9249 | BX33: =BX18+BX24+BX32 -> 3942.0306 | BY33: =BY18+BY24+BY32 -> 4657.8092 | BZ33: =BZ18+BZ24+BZ32 -> 4477.1569
A35: Остаток денежных средств на конец периода | B35: =B3+B33 -> 27944.15 | I35: =I3+I33 -> 22519.308 | P35: =P3+P33 -> 35338.17 | W35: =W3+W33 -> 54214.769 | AC35: =AC3+AC33 -> 74124.687 | AI35: =AI3+AI33 -> 92077.029 | AO35: =AO3+AO33 -> 108378.37 | AV35: 13345 | AW35: 8742.35 | AX35: 10673.443 | AY35: 13253.576 | AZ35: 15782.006 | BA35: 17305.874 | BB35: 19053.394 | BD35: =BD3+BD33 -> 12450.95 | BE35: =BE3+BE33 -> 12536.758 | BF35: =BF3+BF33 -> 20000.7 | BG35: =BG3+BG33 -> 27453.85 | BH35: =BH3+BH33 -> 33764.424 | BI35: =BI3+BI33 -> 39974.694 | BJ35: =BJ3+BJ33 -> 46334.846 | BL35: =BL3+BL33 -> 2148.2 | BM35: =BM3+BM33 -> 1240.2 | BN35: =BN3+BN33 -> 4664.0262 | BO35: =BO3+BO33 -> 13507.343 | BP35: =BP3+BP33 -> 24578.257 | BQ35: =BQ3+BQ33 -> 34796.461 | BR35: =BR3+BR33 -> 42990.127 | BT35: =BT3+BT33 -> 3339.75 | BU35: =BU3+BU33 -> 2946.3509 | BV35: =BV3+BV33 -> 5721.2682 | BW35: =BW3+BW33 -> 9039.1932 | BX35: =BX3+BX33 -> 12981.224 | BY35: =BY3+BY33 -> 17639.033 | BZ35: =BZ3+BZ33 -> 22116.19

Sheet ОПУ
A1: Отчёт о прибылях и убытках, тыс. руб. | B1: Консолидация по группе | AZ1: А | BH1: Б | BP1: В | BX1: Г
B2: 2025 план | C2: ВГО 1 | D2: ВГО 2 | E2: ВГО 3 | F2: ВГО 4 | G2: ВГО 5 | H2: Доля ЧП от Г | I2: 2025 факт | J2: ВГО 1 | K2: ВГО 2 | L2: ВГО 3 | M2: ВГО 4 | N2: ВГО 5 | O2: Доля ЧП от Г | P2: 2026 | Q2: ВГО 1 | R2: ВГО 2 | S2: ВГО 3 | T2: ВГО 4 | U2: ВГО 5 | V2: Доля ЧП от Г | W2: 2027 | X2: ВГО 1 | Y2: ВГО 2 | Z2: ВГО 3 | AA2: ВГО 4 | AB2: ВГО 5 | AC2: Доля ЧП от Г | AD2: 2028 | AE2: ВГО 1 | AF2: ВГО 2 | AG2: ВГО 3 | AH2: ВГО 4 | AI2: ВГО 5 | AJ2: Доля ЧП от Г | AK2: 2029 | AL2: ВГО 1 | AM2: ВГО 2 | AN2: ВГО 3 | AO2: ВГО 4 | AP2: ВГО 5 | AQ2: Доля ЧП от Г | AR2: 2030 | AS2: ВГО 1 | AT2: ВГО 2 | AU2: ВГО 3 | AV2: ВГО 4 | AW2: ВГО 5 | AX2: Доля ЧП от Г | AZ2: 2025 план | BA2: 2025 факт | BB2: 2026 | BC2: 2027 | BD2: 2028 | BE2: 2029 | BF2: 2030 | BH2: 2025 план | BI2: 2025 факт | BJ2: 2026 | BK2: 2027 | BL2: 2028 | BM2: 2029 | BN2: 2030 | BP2: 2025 план | BQ2: 2025 факт | BR2: 2026 | BS2: 2027 | BT2: 2028 | BU2: 2029 | BV2: 2030 | BX2: 2025 план | BY2: 2025 факт | BZ2: 2026 | CA2: 2027 | CB2: 2028 | CC2: 2029 | CD2: 2030
A3: Выручка от реализации | B3: =SUM(B4:B8) -> 115131 | I3: =SUM(I4:I8) -> 116763.03 | P3: =SUM(P4:P8) -> 137509.17 | W3: =SUM(W4:W8) -> 163226.35 | AD3: =SUM(AD4:AD8) -> 195015.33 | AK3: =SUM(AK4:AK8) -> 235724.95 | AR3: =SUM(AR4:AR8) -> 287125.81 | AZ3: 51450 | BA3: 51502 | BB3: 59323.437 | BC3: 68332.847 | BD3: 78710.69 | BE3: 90664.845 | BF3: 104434.77 | BH3: 42500 | BI3: 43215.028 | BJ3: 51144.985 | BK3: 60531.073 | BL3: 71640.855 | BM3: 84791.094 | BN3: 100356.8 | BP3: 23700 | BQ3: 24565 | BR3: 29797.345 | BS3: 37246.681 | BT3: 47675.752 | BU3: 63408.75 | BV3: 85601.813 | BX3: 8500 | BY3: 7911.8422 | BZ3: 8873.1311 | CA3: 9951.2165 | CB3: 11160.289 | CC3: 12516.264 | CD3: 14036.991
A4: Комиссии за обработку платежей и переводов | B4: =(AZ4+BH4+BP4)+SUM(C4:H4) -> 51318 | C4: =-Вводные!D23 -> -110 | F4: =-Вводные!D26 -> -22 | I4: =(BA4+BI4+BQ4)+SUM(J4:N4) -> 51370 | J4: =-Вводные!D23 -> -110 | M4: =-Вводные!D26 -> -22 | P4: =(BB4+BJ4+BR4)+SUM(Q4:V4) -> 59184.837 | Q4: =-Вводные!E23 -> -115.5 | T4: =-Вводные!E26 -> -23.1 | W4: =(BC4+BK4+BS4)+SUM(X4:AC4) -> 68187.592 | X4: =-Вводные!F23 -> -121 | AA4: =-Вводные!F26 -> -24.255 | AD4: =(BD4+BL4+BT4)+SUM(AE4:AJ4) -> 78558.722 | AE4: =-Вводные!G23 -> -126.5 | AH4: =-Вводные!G26 -> -25.46775 | AK4: =(BE4+BM4+BU4)+SUM(AL4:AQ4) -> 90506.104 | AL4: =-Вводные!H23 -> -132 | AO4: =-Вводные!H26 -> -26.741138 | AR4: =(BF4+BN4+BV4)+SUM(AS4:AX4) -> 104269.19 | AS4: =-Вводные!I23 -> -137.5 | AV4: =-Вводные!I26 -> -28.078194 | AZ4: 51450 | BA4: 51502 | BB4: 59323.437 | BC4: 68332.847 | BD4: 78710.69 | BE4: 90664.845 | BF4: 104434.77 | BH4: 0 | BI4: 0 | BJ4: 0 | BK4: 0 | BL4: 0 | BM4: 0 | BN4: 0 | BP4: 0 | BQ4: 0 | BR4: 0 | BS4: 0 | BT4: 0 | BU4: 0 | BV4: 0 | BX4: 0 | BY4: 0 | BZ4: 0 | CA4: 0 | CB4: 0 | CC4: 0 | CD4: 0
A5: Разработка программного обеспечения | B5: =(AZ5+BH5+BP5)+SUM(C5:H5) -> 26290 | G5: =-Вводные!D27 -> -1210 | I5: =(BA5+BI5+BQ5)+SUM(J5:O5) -> 26879.768 | N5: =-Вводные!D27 -> -1210 | P5: =(BB5+BJ5+BR5)+SUM(Q5:V5) -> 31825.926 | U5: =-Вводные!E27 -> -1320 | W5: =(BC5+BK5+BS5)+SUM(X5:AC5) -> 37792.193 | AB5: =-Вводные!F27 -> -1320 | AD5: =(BD5+BL5+BT5)+SUM(AE5:AJ5) -> 44832.388 | AI5: =-Вводные!G27 -> -1320 | AK5: =(BE5+BM5+BU5)+SUM(AL5:AQ5) -> 53139.818 | AP5: =-Вводные!H27 -> -1320 | AR5: =(BF5+BN5+BV5)+SUM(AS5:AX5) -> 62942.585 | AW5: =-Вводные!I27 -> -1320 | AZ5: 0 | BA5: 0 | BH5: 27500 | BI5: 28089.768 | BJ5: 33145.926 | BK5: 39112.193 | BL5: 46152.388 | BM5: 54459.818 | BN5: 64262.585 | BP5: 0 | BQ5: 0 | BR5: 0 | BS5: 0 | BT5: 0 | BU5: 0 | BV5: 0 | BX5: 0 | BY5: 0 | BZ5: 0 | CA5: 0 | CB5: 0 | CC5: 0 | CD5: 0
A6: Аутсорсинговые услуги | B6: =(AZ6+BH6+BP6)+SUM(C6:H6) -> 13823 | D6: =-Вводные!D24 -> -1100 | E6: =-Вводные!D25 -> -77 | I6: =(BA6+BI6+BQ6)+SUM(J6:O6) -> 13948.26 | K6: =-Вводные!D24 -> -1100 | L6: =-Вводные!D25 -> -77 | P6: =(BB6+BJ6+BR6)+SUM(Q6:V6) -> 16701.059 | R6: =-Вводные!E24 -> -1210 | S6: =-Вводные!E25 -> -88 | W6: =(BC6+BK6+BS6)+SUM(X6:AC6) -> 19999.88 | Y6: =-Вводные!F24 -> -1320 | Z6: =-Вводные!F25 -> -99 | AD6: =(BD6+BL6+BT6)+SUM(AE6:AJ6) -> 23948.468 | AF6: =-Вводные!G24 -> -1430 | AG6: =-Вводные!G25 -> -110 | AK6: =(BE6+BM6+BU6)+SUM(AL6:AQ6) -> 28670.276 | AM6: =-Вводные!H24 -> -1540 | AN6: =-Вводные!H25 -> -121 | AR6: =(BF6+BN6+BV6)+SUM(AS6:AX6) -> 34312.219 | AT6: =-Вводные!I24 -> -1650 | AU6: =-Вводные!I25 -> -132 | AZ6: 0 | BA6: 0 | BH6: 15000 | BI6: 15125.26 | BJ6: 17999.059 | BK6: 21418.88 | BL6: 25488.468 | BM6: 30331.276 | BN6: 36094.219 | BP6: 0 | BQ6: 0 | BR6: 0 | BS6: 0 | BT6: 0 | BU6: 0 | BV6: 0 | BX6: 0 | BY6: 0 | BZ6: 0 | CA6: 0 | CB6: 0 | CC6: 0 | CD6: 0
A7: Комиссии трейдинговой площадки | B7: =(AZ7+BH7+BP7)+SUM(C7:H7) -> 23700 | I7: =(BA7+BI7+BQ7)+SUM(J7:O7) -> 24565 | P7: =(BB7+BJ7+BR7)+SUM(Q7:V7) -> 29797.345 | W7: =(BC7+BK7+BS7)+SUM(X7:AC7) -> 37246.681 | AD7: =(BD7+BL7+BT7)+SUM(AE7:AJ7) -> 47675.752 | AK7: =(BE7+BM7+BU7)+SUM(AL7:AQ7) -> 63408.75 | AR7: =(BF7+BN7+BV7) -> 85601.813 | AZ7: 0 | BA7: 0 | BH7: 0 | BI7: 0 | BJ7: 0 | BK7: 0 | BL7: 0 | BM7: 0 | BN7: 0 | BP7: 23700 | BQ7: 24565 | BR7: 29797.345 | BS7: 37246.681 | BT7: 47675.752 | BU7: 63408.75 | BV7: 85601.813 | BX7: 0 | BY7: 0 | BZ7: 0 | CA7: 0 | CB7: 0 | CC7: 0 | CD7: 0
A8: Комиссии за услуги бронирования | B8: =(AZ8+BH8+BP8)+SUM(C8:H8) -> 0 | I8: =(BA8+BI8+BQ8)+SUM(J8:O8) -> 0 | P8: =(BB8+BJ8+BR8)+SUM(Q8:V8) -> 0 | W8: =(BC8+BK8+BS8) -> 0 | AD8: =(BD8+BL8+BT8) -> 0 | AK8: =(BE8+BM8+BU8) -> 0 | AR8: =(BF8+BN8+BV8) -> 0 | AZ8: 0 | BA8: 0 | BH8: 0 | BI8: 0 | BJ8: 0 | BK8: 0 | BL8: 0 | BM8: 0 | BN8: 0 | BP8: 0 | BQ8: 0 | BR8: 0 | BS8: 0 | BT8: 0 | BU8: 0 | BV8: 0 | BX8: 8500 | BY8: 7911.8422 | BZ8: 8873.1311 | CA8: 9951.2165 | CB8: 11160.289 | CC8: 12516.264 | CD8: 14036.991
A9: Себестоимость реализации: | B9: =SUM(B10:B12) -> 50290 | I9: =SUM(I10:I12) -> 50750.063 | P9: =SUM(P10:P12) -> 57356.908 | W9: =SUM(W10:W12) -> 64843.676 | AD9: =SUM(AD10:AD12) -> 73210.956 | AK9: =SUM(AK10:AK12) -> 82588.037 | AR9: =SUM(AR10:AR12) -> 93126.421 | AZ9: 17350 | BA9: 17365 | BB9: 19930.159 | BC9: 22647.391 | BD9: 25525.727 | BE9: 28574.739 | BF9: 31804.564 | BH9: 20300 | BI9: 20311.063 | BJ9: 23322.149 | BK9: 26794.159 | BL9: 30798.762 | BM9: 35418.879 | BN9: 40750.465 | BP9: 14950 | BQ9: 15384 | BR9: 16634.6 | BS9: 18042.126 | BT9: 19636.466 | BU9: 21454.42 | BV9: 23541.392 | BX9: 2350 | BY9: 2421.0911 | BZ9: 2569.643 | CA9: 2729.6538 | CB9: 2902.213 | CC9: 3088.5279 | CD9: 3289.9373
A10: Прямые расходы на персонал | B10: =(AZ10+BH10+BP10)+SUM(C10:H10) -> 41960 | D10: =-Вводные!D24 -> -1100 | I10: =(BA10+BI10+BQ10)+SUM(J10:O10) -> 42144.562 | K10: =-Вводные!D24 -> -1100 | P10: =(BB10+BJ10+BR10)+SUM(Q10:V10) -> 47630.464 | R10: =-Вводные!E24 -> -1210 | W10: =(BC10+BK10+BS10)+SUM(X10:AC10) -> 53668.304 | Y10: =-Вводные!F24 -> -1320 | AD10: =(BD10+BL10+BT10)+SUM(AE10:AJ10) -> 60323.627 | AF10: =-Вводные!G24 -> -1430 | AK10: =(BE10+BM10+BU10)+SUM(AL10:AQ10) -> 67670.773 | AM10: =-Вводные!H24 -> -1540 | AR10: =(BF10+BN10+BV10)+SUM(AS10:AX10) -> 75794.136 | AT10: =-Вводные!I24 -> -1650 | AZ10: 13710 | BA10: 13690.913 | BB10: 16072.368 | BC10: 18596.71 | BD10: 21272.513 | BE10: 24108.864 | BF10: 27115.395 | BH10: 16000 | BI10: 16013.648 | BJ10: 18415.696 | BK10: 21178.05 | BL10: 24354.757 | BM10: 28007.971 | BN10: 32209.167 | BP10: 13350 | BQ10: 13540 | BR10: 14352.4 | BS10: 15213.544 | BT10: 16126.357 | BU10: 17093.938 | BV10: 18119.574 | BX10: 1800 | BY10: 1834.98 | BZ10: 1917.5541 | CA10: 2003.844 | CB10: 2094.017 | CC10: 2188.2478 | CD10: 2286.7189
A11: Оборудование, лицензии и программное обеспечение | B11: =(AZ11+BH11+BP11)+SUM(C11:H11) -> 6640 | G11: =-Вводные!D27 -> -1210 | I11: =(BA11+BI11+BQ11)+SUM(J11:O11) -> 6977.7896 | N11: =-Вводные!D27 -> -1210 | P11: =(BB11+BJ11+BR11)+SUM(Q11:V11) -> 8009.5555 | U11: =-Вводные!E27 -> -1320 | W11: =(BC11+BK11+BS11)+SUM(X11:AC11) -> 9364.4122 | AB11: =-Вводные!F27 -> -1320 | AD11: =(BD11+BL11+BT11)+SUM(AE11:AJ11) -> 10977.136 | AI11: =-Вводные!G27 -> -1320 | AK11: =(BE11+BM11+BU11)+SUM(AL11:AQ11) -> 12902.392 | AP11: =-Вводные!H27 -> -1320 | AR11: =(BF11+BN11+BV11)+SUM(AS11:AX11) -> 15206.988 | AW11: =-Вводные!I27 -> -1320 | AZ11: 3450 | BA11: 3484.7242 | BB11: 3658.9604 | BC11: 3841.9085 | BD11: 4034.0039 | BE11: 4235.7041 | BF11: 4447.4893 | BH11: 2900 | BI11: 2979.0654 | BJ11: 3515.595 | BK11: 4148.7537 | BL11: 4895.9443 | BM11: 5777.7038 | BN11: 6818.2683 | BP11: 1500 | BQ11: 1724 | BR11: 2155 | BS11: 2693.75 | BT11: 3367.1875 | BU11: 4208.9844 | BV11: 5261.2305 | BX11: 500 | BY11: 531.66667 | BZ11: 595.46667 | CA11: 666.92267 | CB11: 746.95339 | CC11: 836.58779 | CD11: 936.97833
A12: Прочие расходы | B12: =(AZ12+BH12+BP12)+SUM(C12:H12) -> 1690 | I12: =(BA12+BI12+BQ12)+SUM(J12:O12) -> 1627.7118 | P12: =(BB12+BJ12+BR12)+SUM(Q12:V12) -> 1716.8892 | W12: =(BC12+BK12+BS12) -> 1810.9599 | AD12: =(BD12+BL12+BT12) -> 1910.193 | AK12: =(BE12+BM12+BU12) -> 2014.8722 | AR12: =(BF12+BN12+BV12) -> 2125.2968 | AZ12: 190 | BA12: 189.36247 | BB12: 198.83059 | BC12: 208.77212 | BD12: 219.21073 | BE12: 230.17127 | BF12: 241.67983 | BH12: 1400 | BI12: 1318.3494 | BJ12: 1390.8586 | BK12: 1467.3558 | BL12: 1548.0604 | BM12: 1633.2037 | BN12: 1723.0299 | BP12: 100 | BQ12: 120 | BR12: 127.2 | BS12: 134.832 | BT12: 142.92192 | BU12: 151.49724 | BV12: 160.58707 | BX12: 50 | BY12: 54.444444 | BZ12: 56.622222 | CA12: 58.887111 | CB12: 61.242596 | CC12: 63.692299 | CD12: 66.239991
A13: Валовая прибыль | B13: =B3-B9 -> 64841 | I13: =I3-I9 -> 66012.965 | P13: =P3-P9 -> 80152.259 | W13: =W3-W9 -> 98382.67 | AD13: =AD3-AD9 -> 121804.37 | AK13: =AK3-AK9 -> 153136.91 | AR13: =AR3-AR9 -> 193999.39 | AZ13: 34100 | BA13: 34137 | BB13: 39393.278 | BC13: 45685.456 | BD13: 53184.963 | BE13: 62090.106 | BF13: 72630.208 | BH13: 22200 | BI13: 22903.965 | BJ13: 27822.836 | BK13: 33736.914 | BL13: 40842.093 | BM13: 49372.216 | BN13: 59606.339 | BP13: 8750 | BQ13: 9181 | BR13: 13162.745 | BS13: 19204.555 | BT13: 28039.286 | BU13: 41954.331 | BV13: 62060.421 | BX13: 6150 | BY13: 5490.7511 | BZ13: 6303.4881 | CA13: 7221.5627 | CB13: 8258.0763 | CC13: 9427.7365 | CD13: 10747.053
A14: Операционные расходы | B14: =SUM(B15:B19) -> 38032 | I14: =SUM(I15:I19) -> 38479.669 | P14: =SUM(P15:P19) -> 41615.091 | W14: =SUM(W15:W19) -> 44770.252 | AD14: =SUM(AD15:AD19) -> 48203.285 | AK14: =SUM(AK15:AK19) -> 51942.29 | AR14: =SUM(AR15:AR19) -> 56200.83 | AZ14: 15614 | BA14: 15549 | BB14: 16723.397 | BC14: 17694.808 | BD14: 18689.512 | BE14: 19698.538 | BF14: 20710.006 | BH14: 13878 | BI14: 14001.669 | BJ14: 14840.865 | BK14: 15731.053 | BL14: 16675.378 | BM14: 17677.179 | BN14: 18740.005 | BP14: 8749 | BQ14: 9138 | BR14: 10277.43 | BS14: 11588.646 | BT14: 13100.363 | BU14: 14846.314 | BV14: 17048.397 | BX14: 3945 | BY14: 3944.4444 | BZ14: 4136.4444 | CA14: 4338.4894 | CB14: 4551.1619 | CC14: 4775.0825 | CD14: 5010.9125
A15: Расходы на персонал | B15: =(AZ15+BH15+BP15)+SUM(C15:H15) -> 14623 | E15: =-Вводные!D25 -> -77 | I15: =(BA15+BI15+BQ15)+SUM(J15:O15) -> 14650.085 | L15: =-Вводные!D25 -> -77 | P15: =(BB15+BJ15+BR15)+SUM(Q15:V15) -> 15595.929 | S15: =-Вводные!E25 -> -88 | W15: =(BC15+BK15+BS15)+SUM(X15:AC15) -> 16604.31 | Z15: =-Вводные!F25 -> -99 | AD15: =(BD15+BL15+BT15)+SUM(AE15:AJ15) -> 17679.337 | AG15: =-Вводные!G25 -> -110 | AK15: =(BE15+BM15+BU15)+SUM(AL15:AQ15) -> 18825.394 | AN15: =-Вводные!H25 -> -121 | AR15: =(BF15+BN15+BV15)+SUM(AS15:AX15) -> 20047.153 | AU15: =-Вводные!I25 -> -132 | AZ15: 7400 | BA15: 7405.1667 | BB15: 7849.4767 | BC15: 8320.4453 | BD15: 8819.672 | BE15: 9348.8523 | BF15: 9909.7834 | BH15: 4600 | BI15: 4606.9184 | BJ15: 4929.4027 | BK15: 5274.4609 | BL15: 5643.6731 | BM15: 6038.7303 | BN15: 6461.4414 | BP15: 2700 | BQ15: 2715 | BR15: 2905.05 | BS15: 3108.4035 | BT15: 3325.9917 | BU15: 3558.8112 | BV15: 3807.9279 | BX15: 3180 | BY15: 3177.7778 | BZ15: 3320.7778 | CA15: 3470.2128 | CB15: 3626.3724 | CC15: 3789.5591 | CD15: 3960.0893
A16: Аренда | B16: =(AZ16+BH16+BP16)+SUM(C16:H16) -> 2191 | I16: =(BA16+BI16+BQ16)+SUM(J16:O16) -> 2190.7038 | P16: =(BB16+BJ16+BR16)+SUM(Q16:V16) -> 2309.6184 | W16: =(BC16+BK16+BS16) -> 2435.022 | AD16: =(BD16+BL16+BT16) -> 2567.2706 | AK16: =(BE16+BM16+BU16) -> 2706.7398 | AR16: =(BF16+BN16+BV16) -> 2853.826 | AZ16: 864 | BA16: 863.83333 | BB16: 907.025 | BC16: 952.37625 | BD16: 999.99506 | BE16: 1049.9948 | BF16: 1102.4946 | BH16: 778 | BI16: 777.8705 | BJ16: 820.65338 | BK16: 865.78931 | BL16: 913.40773 | BM16: 963.64515 | BN16: 1016.6456 | BP16: 549 | BQ16: 549 | BR16: 581.94 | BS16: 616.8564 | BT16: 653.86778 | BU16: 693.09985 | BV16: 734.68584 | BX16: 200 | BY16: 200 | BZ16: 208 | CA16: 216.32 | CB16: 224.9728 | CC16: 233.97171 | CD16: 243.33058
A17: Реклама и маркетинг | B17: =(AZ17+BH17+BP17)+SUM(C17:H17) -> 15000 | I17: =(BA17+BI17+BQ17)+SUM(J17:O17) -> 15338.189 | P17: =(BB17+BJ17+BR17)+SUM(Q17:V17) -> 17073.35 | W17: =(BC17+BK17+BS17) -> 18740.989 | AD17: =(BD17+BL17+BT17) -> 20593.794 | AK17: =(BE17+BM17+BU17) -> 22654.071 | AR17: =(BF17+BN17+BV17) -> 25129.228 | AZ17: 3800 | BA17: 3767 | BB17: 4278.245 | BC17: 4548.9038 | BD17: 4803.1085 | BE17: 5029.617 | BF17: 5214.1513 | BH17: 6800 | BI17: 6871.1894 | BJ17: 7249.1048 | BK17: 7647.8056 | BL17: 8068.4349 | BM17: 8512.1988 | BN17: 8980.3698 | BP17: 4400 | BQ17: 4700 | BR17: 5546 | BS17: 6544.28 | BT17: 7722.2504 | BU17: 9112.2555 | BV17: 10934.707 | BX17: 360 | BY17: 366.66667 | BZ17: 399.66667 | CA17: 435.63667 | CB17: 474.84397 | CC17: 517.57992 | CD17: 564.16212
A18: Оборудование, лицензии и программное обеспечение | B18: =(AZ18+BH18+BP18)+SUM(C18:H18) -> 4850 | I18: =(BA18+BI18+BQ18)+SUM(J18:O18) -> 4910.741 | P18: =(BB18+BJ18+BR18)+SUM(Q18:V18) -> 5174.2968 | W18: =(BC18+BK18+BS18) -> 5452.0725 | AD18: =(BD18+BL18+BT18) -> 5744.8397 | AK18: =(BE18+BM18+BU18) -> 6053.4118 | AR18: =(BF18+BN18+BV18) -> 6378.6466 | AZ18: 2350 | BA18: 2331 | BB18: 2447.55 | BC18: 2569.9275 | BD18: 2698.4239 | BE18: 2833.3451 | BF18: 2975.0123 | BH18: 1500 | BI18: 1555.741 | BJ18: 1641.3068 | BK18: 1731.5786 | BL18: 1826.8155 | BM18: 1927.2903 | BN18: 2033.2913 | BP18: 1000 | BQ18: 1024 | BR18: 1085.44 | BS18: 1150.5664 | BT18: 1219.6004 | BU18: 1292.7764 | BV18: 1370.343 | BX18: 200 | BY18: 196 | BZ18: 203.84 | CA18: 211.9936 | CB18: 220.47334 | CC18: 229.29228 | CD18: 238.46397
A19: Прочие расходы | B19: =(AZ19+BH19+BP19)+SUM(C19:H19) -> 1368 | C19: =-Вводные!D23 -> -110 | F19: =-Вводные!D26 -> -22 | I19: =(BA19+BI19+BQ19)+SUM(J19:O19) -> 1389.9497 | J19: =-Вводные!D23 -> -110 | L19: =-Вводные!D26 -> -22 | P19: =(BB19+BJ19+BR19)+SUM(Q19:V19) -> 1461.8969 | Q19: =-Вводные!E23 -> -115.5 | S19: =-Вводные!E26 -> -23.1 | W19: =(BC19+BK19+BS19)+SUM(X19:AC19) -> 1537.8588 | X19: =-Вводные!F23 -> -121 | Z19: =-Вводные!F26 -> -24.255 | AD19: =(BD19+BL19+BT19)+SUM(AE19:AJ19) -> 1618.0442 | AE19: =-Вводные!G23 -> -126.5 | AG19: =-Вводные!G26 -> -25.46775 | AK19: =(BE19+BM19+BU19)+SUM(AL19:AQ19) -> 1702.6732 | AL19: =-Вводные!H23 -> -132 | AN19: =-Вводные!H26 -> -26.741138 | AR19: =(BF19+BN19+BV19)+SUM(AS19:AX19) -> 1791.9771 | AS19: =-Вводные!I23 -> -137.5 | AU19: =-Вводные!I26 -> -28.078194 | AZ19: 1200 | BA19: 1182 | BB19: 1241.1 | BC19: 1303.155 | BD19: 1368.3128 | BE19: 1436.7284 | BF19: 1508.5648 | BH19: 200 | BI19: 189.94969 | BJ19: 200.39692 | BK19: 211.41875 | BL19: 223.04679 | BM19: 235.31436 | BN19: 248.25665 | BP19: 100 | BQ19: 150 | BR19: 159 | BS19: 168.54 | BT19: 178.6524 | BU19: 189.37154 | BV19: 200.73384 | BX19: 5 | BY19: 4 | BZ19: 4.16 | CA19: 4.3264 | CB19: 4.499456 | CC19: 4.6794342 | CD19: 4.8666116
A20: Операционная прибыль | B20: =B13-B14 -> 26809 | I20: =I13-I14 -> 27533.296 | P20: =P13-P14 -> 38537.168 | W20: =W13-W14 -> 53612.418 | AD20: =AD13-AD14 -> 73601.089 | AK20: =AK13-AK14 -> 101194.62 | AR20: =AR13-AR14 -> 137798.56 | AZ20: 18486 | BA20: 18588 | BB20: 22669.881 | BC20: 27990.648 | BD20: 34495.45 | BE20: 42391.569 | BF20: 51920.202 | BH20: 8322 | BI20: 8902.2957 | BJ20: 12981.972 | BK20: 18005.861 | BL20: 24166.715 | BM20: 31695.037 | BN20: 40866.334 | BP20: 1 | BQ20: 43 | BR20: 2885.315 | BS20: 7615.909 | BT20: 14938.923 | BU20: 27108.016 | BV20: 45012.024 | BX20: 2205 | BY20: 1546.3067 | BZ20: 2167.0436 | CA20: 2883.0732 | CB20: 3706.9144 | CC20: 4652.6541 | CD20: 5736.1408
A21: Внереализационные доходы | B21: =SUM(B22:B24) -> 2274.125 | I21: =SUM(I22:I24) -> 2205.3063 | P21: =SUM(P22:P24) -> 2370.2791 | W21: =SUM(W22:W24) -> 2558.0176 | AD21: =SUM(AD22:AD24) -> 2771.4082 | AK21: =SUM(AK22:AK24) -> 3013.6936 | AR21: =SUM(AR22:AR24) -> 3288.5167 | AZ21: 359 | BA21: 385 | BB21: 398.8 | BC21: 413.29 | BD21: 428.5045 | BE21: 444.47973 | BF21: 461.25371 | BH21: 619 | BI21: 668.71228 | BJ21: 679.71228 | BK21: 691.31728 | BL21: 703.56055 | BM21: 716.47721 | BN21: 730.10428 | BP21: 800 | BQ21: 803 | BR21: 803.48 | BS21: 803.9888 | BT21: 804.52813 | BU21: 805.09982 | BV21: 805.7058 | BX21: 10 | BY21: 15 | BZ21: 15.6 | CA21: 16.224 | CB21: 16.87296 | CC21: 17.547878 | CD21: 18.249794
A22: Инвестиционный доход | B22: =(AZ22+BH22+BP22)+SUM(C22:H22) -> 1373 | I22: =(BA22+BI22+BQ22)+SUM(J22:O22) -> 1372.7123 | P22: =(BB22+BJ22+BR22)+SUM(Q22:V22) -> 1372.7123 | W22: =(BC22+BK22+BS22) -> 1372.7123 | AD22: =(BD22+BL22+BT22) -> 1372.7123 | AK22: =(BE22+BM22+BU22) -> 1372.7123 | AR22: =(BF22+BN22+BV22) -> 1372.7123 | AZ22: 109 | BA22: 109 | BB22: 109 | BC22: 109 | BD22: 109 | BE22: 109 | BF22: 109 | BH22: 469 | BI22: 468.71228 | BJ22: 468.71228 | BK22: 468.71228 | BL22: 468.71228 | BM22: 468.71228 | BN22: 468.71228 | BP22: 795 | BQ22: 795 | BR22: 795 | BS22: 795 | BT22: 795 | BU22: 795 | BV22: 795 | BX22: 0 | BY22: 0 | BZ22: 0 | CA22: 0 | CB22: 0 | CC22: 0 | CD22: 0
A23: Прочие доходы | B23: =(AZ23+BH23+BP23)+SUM(C23:H23) -> 405 | I23: =(BA23+BI23+BQ23)+SUM(J23:O23) -> 484 | P23: =(BB23+BJ23+BR23)+SUM(Q23:V23) -> 509.28 | W23: =(BC23+BK23+BS23) -> 535.8838 | AD23: =(BD23+BL23+BT23) -> 563.8809 | AK23: =(BE23+BM23+BU23) -> 593.34447 | AR23: =(BF23+BN23+BV23) -> 624.35152 | AZ23: 250 | BA23: 276 | BB23: 289.8 | BC23: 304.29 | BD23: 319.5045 | BE23: 335.47973 | BF23: 352.25371 | BH23: 150 | BI23: 200 | BJ23: 211 | BK23: 222.605 | BL23: 234.84827 | BM23: 247.76493 | BN23: 261.392 | BP23: 5 | BQ23: 8 | BR23: 8.48 | BS23: 8.9888 | BT23: 9.528128 | BU23: 10.099816 | BV23: 10.705805 | BX23: 10 | BY23: 15 | BZ23: 15.6 | CA23: 16.224 | CB23: 16.87296 | CC23: 17.547878 | CD23: 18.249794
A24: Доля прибыли ассоциированной компании | B24: =H24 -> 496.125 | H24: =BX30*30% -> 496.125 | I24: =O24 -> 348.594 | O24: =BY30*30% -> 348.594 | P24: =V24 -> 488.28681 | V24: =BZ30*30% -> 488.28681 | W24: =AC24 -> 649.42155 | AC24: =CA30*30% -> 649.42155 | AD24: =AJ24 -> 834.81501 | AJ24: =CB30*30% -> 834.81501 | AK24: =AQ24 -> 1047.6368 | AQ24: =CC30*30% -> 1047.6368 | AR24: =AX24 -> 1291.4529 | AX24: =CD30*30% -> 1291.4529
A25: Внереализационные расходы | B25: =SUM(B26:B27) -> 186 | I25: =SUM(I26:I27) -> 210 | P25: =SUM(P26:P27) -> 218.55 | W25: =SUM(W26:W27) -> 176.561 | AD25: =SUM(AD26:AD27) -> 186.05792 | AK25: =SUM(AK26:AK27) -> 196.06704 | AR25: =SUM(AR26:AR27) -> 206.61605 | AZ25: 101 | BA25: 100 | BB25: 102.45 | BC25: 54.0225 | BD25: 56.723625 | BE25: 59.559806 | BF25: 62.537797 | BH25: 80 | BI25: 100 | BJ25: 105.5 | BK25: 111.3025 | BL25: 117.42414 | BM25: 123.88247 | BN25: 130.696 | BP25: 5 | BQ25: 10 | BR25: 10.6 | BS25: 11.236 | BT25: 11.91016 | BU25: 12.62477 | BV25: 13.382256 | BX25: 10 | BY25: 12 | BZ25: 12.48 | CA25: 12.9792 | CB25: 13.498368 | CC25: 14.038303 | CD25: 14.599835
A26: Проценты уплаченные (аннуитет, полное погашение долга в конце 2026) | B26: =AZ26+BH26+BP26 -> 51 | I26: =(BA26+BI26+BQ26)+SUM(J26:O26) -> 51 | P26: =(BB26+BJ26+BR26)+SUM(Q26:V26) -> 51 | W26: =(BC26+BK26+BS26) -> 0 | AD26: =(BD26+BL26+BT26) -> 0 | AK26: =(BE26+BM26+BU26) -> 0 | AR26: =(BF26+BN26+BV26) -> 0 | AZ26: 51 | BA26: 51 | BB26: 51 | BC26: 0 | BD26: 0 | BE26: 0 | BF26: 0 | BH26: 0 | BI26: 0 | BJ26: 0 | BK26: 0 | BL26: 0 | BM26: 0 | BN26: 0 | BP26: 0 | BQ26: 0 | BR26: 0 | BS26: 0 | BT26: 0 | BU26: 0 | BV26: 0 | BX26: 0 | BY26: 0 | BZ26: 0 | CA26: 0 | CB26: 0 | CC26: 0 | CD26: 0
A27: Прочие расходы | B27: =AZ27+BH27+BP27 -> 135 | I27: =(BA27+BI27+BQ27)+SUM(J27:O27) -> 159 | P27: =(BB27+BJ27+BR27)+SUM(Q27:V27) -> 167.55 | W27: =(BC27+BK27+BS27) -> 176.561 | AD27: =(BD27+BL27+BT27) -> 186.05792 | AK27: =(BE27+BM27+BU27) -> 196.06704 | AR27: =(BF27+BN27+BV27) -> 206.61605 | AZ27: 50 | BA27: 49 | BB27: 51.45 | BC27: 54.0225 | BD27: 56.723625 | BE27: 59.559806 | BF27: 62.537797 | BH27: 80 | BI27: 100 | BJ27: 105.5 | BK27: 111.3025 | BL27: 117.42414 | BM27: 123.88247 | BN27: 130.696 | BP27: 5 | BQ27: 10 | BR27: 10.6 | BS27: 11.236 | BT27: 11.91016 | BU27: 12.62477 | BV27: 13.382256 | BX27: 10 | BY27: 12 | BZ27: 12.48 | CA27: 12.9792 | CB27: 13.498368 | CC27: 14.038303 | CD27: 14.599835
A28: Прибыль до налогообложения | B28: =B20+B21-B25 -> 28897.125 | I28: =I20+I21-I25 -> 29528.602 | P28: =P20+P21-P25 -> 40688.897 | W28: =W20+W21-W25 -> 55993.874 | AD28: =AD20+AD21-AD25 -> 76186.439 | AK28: =AK20+AK21-AK25 -> 104012.25 | AR28: =AR20+AR21-AR25 -> 140880.46 | AZ28: 18744 | BA28: 18873 | BB28: 22966.231 | BC28: 28349.916 | BD28: 34867.231 | BE28: 42776.489 | BF28: 52318.918 | BH28: 8861 | BI28: 9471.008 | BJ28: 13556.184 | BK28: 18585.876 | BL28: 24752.852 | BM28: 32287.631 | BN28: 41465.743 | BP28: 796 | BQ28: 836 | BR28: 3678.195 | BS28: 8408.6617 | BT28: 15731.541 | BU28: 27900.491 | BV28: 45804.347 | BX28: 2205 | BY28: 1549.3067 | BZ28: 2170.1636 | CA28: 2886.318 | CB28: 3710.289 | CC28: 4656.1637 | CD28: 5739.7907
A29: Налог на прибыль | B29: =AZ29+BH29+BP29 -> 7100.25 | I29: =BA29+BI29+BQ29 -> 7295.002 | P29: =(BB29+BJ29+BR29) -> 10050.153 | W29: =(BC29+BK29+BS29) -> 13836.113 | AD29: =(BD29+BL29+BT29) -> 18837.906 | AK29: =(BE29+BM29+BU29) -> 25741.153 | AR29: =(BF29+BN29+BV29) -> 34897.252 | AZ29: 4686 | BA29: 4718.25 | BB29: 5741.5578 | BC29: 7087.4789 | BD29: 8716.8078 | BE29: 10694.122 | BF29: 13079.729 | BH29: 2215.25 | BI29: 2367.752 | BJ29: 3389.046 | BK29: 4646.4689 | BL29: 6188.2129 | BM29: 8071.9078 | BN29: 10366.436 | BP29: 199 | BQ29: 209 | BR29: 919.54875 | BS29: 2102.1654 | BT29: 3932.8853 | BU29: 6975.1228 | BV29: 11451.087 | BX29: 551.25 | BY29: 387.32667 | BZ29: 542.5409 | CA29: 721.5795 | CB29: 927.57224 | CC29: 1164.0409 | CD29: 1434.9477
A30: Чистая прибыль | B30: =B28-B29 -> 21796.875 | I30: =I28-I29 -> 22233.6 | P30: =P28-P29 -> 30638.744 | W30: =W28-W29 -> 42157.761 | AD30: =AD28-AD29 -> 57348.533 | AK30: =AK28-AK29 -> 78271.095 | AR30: =AR28-AR29 -> 105983.21 | AZ30: 14058 | BA30: 14154.75 | BB30: 17224.673 | BC30: 21262.437 | BD30: 26150.424 | BE30: 32082.366 | BF30: 39239.188 | BH30: 6645.75 | BI30: 7103.256 | BJ30: 10167.138 | BK30: 13939.407 | BL30: 18564.639 | BM30: 24215.724 | BN30: 31099.307 | BP30: 597 | BQ30: 627 | BR30: 2758.6462 | BS30: 6306.4963 | BT30: 11798.656 | BU30: 20925.368 | BV30: 34353.26 | BX30: 1653.75 | BY30: 1161.98 | BZ30: 1627.6227 | CA30: 2164.7385 | CB30: 2782.7167 | CC30: 3492.1228 | CD30: 4304.843
A31: принадлежащей группе | B31: =B30-B32 -> 20893.5 | I31: =I30-I32 -> 21272.474 | P31: =P30-P32 -> 28518.572 | W31: =W30-W32 -> 38241.222 | AD31: =AD30-AD32 -> 50772.607 | AK31: =AK30-AK32 -> 67479.375 | AR31: =AR30-AR32 -> 89131.974
A32: принадлежащей неконтролируещей доли | B32: =(BH30*10%)+(BP30*40%) -> 903.375 | I32: =(BI30*10%)+(BQ30*40%) -> 961.1256 | P32: =(BJ30*10%)+(BR30*40%) -> 2120.1723 | W32: =(BK30*10%)+(BS30*40%) -> 3916.5392 | AD32: =(BL30*10%)+(BT30*40%) -> 6575.9262 | AK32: =(BM30*10%)+(BU30*40%) -> 10791.72 | AR32: =(BN30*10%)+(BV30*40%) -> 16851.235
A33: в т. ч. амортизация | B33: =AZ33+BH33+BP33 -> 4254 | I33: =BA33+BI33+BQ33 -> 4253.8487 | P33: =(BB33+BJ33+BR33) -> 3299.28 | W33: =(BC33+BK33+BS33) -> 4729.3668 | AD33: =(BD33+BL33+BT33) -> 4986.7699 | AK33: =(BE33+BM33+BU33) -> 5258.2299 | AR33: =(BF33+BN33+BV33) -> 5544.517 | AZ33: 1132 | BA33: 1132 | BB33: 1188.6 | BC33: 1248.03 | BD33: 1310.4315 | BE33: 1375.9531 | BF33: 1444.7507 | BH33: 2494 | BI33: 2493.8487 | BJ33: 1445 | BK33: 2775.716 | BL33: 2928.3804 | BM33: 3089.4413 | BN33: 3259.3606 | BP33: 628 | BQ33: 628 | BR33: 665.68 | BS33: 705.6208 | BT33: 747.95805 | BU33: 792.83553 | BV33: 840.40566 | BX33: 142 | BY33: 141.62944 | BZ33: 147.29462 | CA33: 153.18641 | CB33: 159.31386 | CC33: 165.68642 | CD33: 172.31387
A34: EBITDA | B34: =B30+B29+B26-B22+B33 -> 31829.125 | I34: =I30+I29+I26-I22+I33 -> 32460.738 | P34: =P30+P29+P26-P22+P33 -> 42666.465 | W34: =W30+W29+W26-W22+W33 -> 59350.529 | AD34: =AD30+AD29+AD26-AD22+AD33 -> 79800.497 | AK34: =AK30+AK29+AK26-AK22+AK33 -> 107897.77 | AR34: =AR30+AR29+AR26-AR22+AR33 -> 145052.26 | AZ34: 19818 | BA34: 19947 | BB34: 24096.831 | BC34: 29488.946 | BD34: 36068.663 | BE34: 44043.442 | BF34: 53654.668 | BH34: 10886 | BI34: 11496.144 | BJ34: 14532.472 | BK34: 20892.879 | BL34: 27212.52 | BM34: 34908.36 | BN34: 44256.391 | BP34: 629 | BQ34: 669 | BR34: 3548.875 | BS34: 8319.2825 | BT34: 15684.499 | BU34: 27898.327 | BV34: 45849.753 | BX34: 2347 | BY34: 1690.9361 | BZ34: 2317.4582 | CA34: 3039.5044 | CB34: 3869.6028 | CC34: 4821.8501 | CD34: 5912.1046

Sheet Баланс
A1: Управленческий баланс*, тыс. руб. | B1: Консолидация по группе | AZ1: А | BH1: Б | BP1: В | BX1: Г
B2: 2025 план | C2: Неконтролирующая доля меньшиства | D2: Нераспределенная прибыль | E2: Акционерный капитал | F2: Беспроцентный заём | G2: Инвестиции в компанию Г | H2: Инвестиции в дочернии компании | I2: 2025 факт | J2: Без контроля доля меньшиства | K2: Нераспределнная прибыль | L2: Акционерный капитал | M2: Беспроцентный заём | N2: Инвестиции в компанию Г | O2: Инвестиции в дочернии компании | P2: 2026 | Q2: Без контроля доля меньшиства | R2: Нераспределнная прибыль | S2: Акционерный капитал | T2: Беспроцентный заём | U2: Инвестиции в компанию Г | V2: Инвестиции в дочернии компании | W2: 2027 | X2: Без контроля доля меньшиства | Y2: Нераспределнная прибыль | Z2: Акционерный капитал | AA2: Беспроцентный заём | AB2: Инвестиции в компанию Г | AC2: Инвестиции в дочернии компании | AD2: 2028 | AE2: Без контроля доля меньшиства | AF2: Нераспределнная прибыль | AG2: Акционерный капитал | AH2: Беспроцентный заём | AI2: Инвестиции в компанию Г | AJ2: Инвестиции в дочернии компании | AK2: 2029 | AL2: Без контроля доля меньшиства | AM2: Нераспределнная прибыль | AN2: Акционерный капитал | AO2: Беспроцентный заём | AP2: Инвестиции в компанию Г | AQ2: Инвестиции в дочернии компании | AR2: 2030 | AS2: Без контроля доля меньшиства | AT2: Нераспределнная прибыль | AU2: Акционерный капитал | AV2: Беспроцентный заём | AW2: Инвестиции в компанию Г | AX2: Инвестиции в дочернии компании | AZ2: 31.12.25 план | BA2: 31.12.25 факт | BB2: 31.12.26 | BC2: 31.12.27 | BD2: 31.12.28 | BE2: 31.12.29 | BF2: 31.12.30 | BH2: 31.12.25 план | BI2: 31.12.25 факт | BJ2: 31.12.26 | BK2: 31.12.27 | BL2: 31.12.28 | BM2: 31.12.29 | BN2: 31.12.30 | BP2: 31.12.25 план | BQ2: 31.12.25 факт | BR2: 31.12.26 | BS2: 31.12.27 | BT2: 31.12.28 | BU2: 31.12.29 | BV2: 31.12.30 | BX2: 31.12.25 план | BY2: 31.12.25 факт | BZ2: 31.12.26 | CA2: 31.12.27 | CB2: 31.12.28 | CC2: 31.12.29 | CD2: 31.12.30
A3: АКТИВЫ | B3: =B4+B13 -> 133757.88 | I3: =I4+I13 -> 131344.52 | P3: =P4+P13 -> 140159.11 | W3: =W4+W13 -> 154951.45 | AD3: =AD4+AD13 -> 170708 | AK3: =AK4+AK13 -> 184451.18 | AR3: =AR4+AR13 -> 196203.69 | AZ3: =AZ4+AZ13 -> 66691.8 | BA3: =BA4+BA13 -> 64982.35 | BB3: =BB4+BB13 -> 65053.023 | BC3: =BC4+BC13 -> 66315.46 | BD3: =BD4+BD13 -> 67465.884 | BE3: =BE4+BE13 -> 67548.25 | BF3: =BF4+BF13 -> 67787.438 | BH3: 53576.95 | BI3: 53768.641 | BJ3: 58666.124 | BK3: 63408.91 | BL3: 66857.266 | BM3: 70045.078 | BN3: 73213.683 | BP3: 16911.2 | BQ3: 16086.2 | BR3: 18844.346 | BS3: 26982.043 | BT3: 37304.998 | BU3: 46730.367 | BV3: 54083.627 | BX3: 4995.75 | BY3: 4633.1731 | BZ3: 7260.7958 | CA3: 10425.534 | CB3: 14208.251 | CC3: 18700.374 | CD3: 23005.217
